2025-08-06 20:50:46,215 INFO sqlalchemy.engine.Engine BEGIN (implicit)
2025-08-06 20:50:46,228 INFO sqlalchemy.engine.Engine SELECT categories.id, categories.name
FROM categories
2025-08-06 20:50:46,228 INFO sqlalchemy.engine.Engine [generated in 0.00020s] ()
2025-08-06 20:50:46,230 INFO sqlalchemy.engine.Engine ROLLBACK
Traceback (most recent call last):
  File "/Volumes/SONICDRIVE/SONICNewProjects/Aug-1-User-Cafe-Models/venv/lib/python3.10/site-packages/sqlalchemy/engine/base.py", line 1961, in _exec_single_context
    self.dialect.do_execute(
  File "/Volumes/SONICDRIVE/SONICNewProjects/Aug-1-User-Cafe-Models/venv/lib/python3.10/site-packages/sqlalchemy/engine/default.py", line 944, in do_execute
    cursor.execute(statement, parameters)
  File "/Volumes/SONICDRIVE/SONICNewProjects/Aug-1-User-Cafe-Models/venv/lib/python3.10/site-packages/sqlalchemy/dialects/sqlite/aiosqlite.py", line 177, in execute
    self._adapt_connection._handle_exception(error)
  File "/Volumes/SONICDRIVE/SONICNewProjects/Aug-1-User-Cafe-Models/venv/lib/python3.10/site-packages/sqlalchemy/dialects/sqlite/aiosqlite.py", line 337, in _handle_exception
    raise error
  File "/Volumes/SONICDRIVE/SONICNewProjects/Aug-1-User-Cafe-Models/venv/lib/python3.10/site-packages/sqlalchemy/dialects/sqlite/aiosqlite.py", line 159, in execute
    self.await_(_cursor.execute(operation, parameters))
  File "/Volumes/SONICDRIVE/SONICNewProjects/Aug-1-User-Cafe-Models/venv/lib/python3.10/site-packages/sqlalchemy/util/_concurrency_py3k.py", line 132, in await_only
    return current.parent.switch(awaitable)  # type: ignore[no-any-return,attr-defined] # noqa: E501
  File "/Volumes/SONICDRIVE/SONICNewProjects/Aug-1-User-Cafe-Models/venv/lib/python3.10/site-packages/sqlalchemy/util/_concurrency_py3k.py", line 196, in greenlet_spawn
    value = await result
  File "/Volumes/SONICDRIVE/SONICNewProjects/Aug-1-User-Cafe-Models/venv/lib/python3.10/site-packages/aiosqlite/cursor.py", line 40, in execute
    await self._execute(self._cursor.execute, sql, parameters)
  File "/Volumes/SONICDRIVE/SONICNewProjects/Aug-1-User-Cafe-Models/venv/lib/python3.10/site-packages/aiosqlite/cursor.py", line 32, in _execute
    return await self._conn._execute(fn, *args, **kwargs)
  File "/Volumes/SONICDRIVE/SONICNewProjects/Aug-1-User-Cafe-Models/venv/lib/python3.10/site-packages/aiosqlite/core.py", line 122, in _execute
    return await future
  File "/Volumes/SONICDRIVE/SONICNewProjects/Aug-1-User-Cafe-Models/venv/lib/python3.10/site-packages/aiosqlite/core.py", line 105, in run
    result = function()
sqlite3.OperationalError: no such table: categories

The above exception was the direct cause of the following exception:

Traceback (most recent call last):
  File "/Volumes/SONICDRIVE/SONICNewProjects/Aug-1-User-Cafe-Models/app/app_data/seed_magic_v1/seed_db.py", line 167, in <module>
    asyncio.run(main())
  File "/Library/Frameworks/Python.framework/Versions/3.10/lib/python3.10/asyncio/runners.py", line 44, in run
    return loop.run_until_complete(main)
  File "/Library/Frameworks/Python.framework/Versions/3.10/lib/python3.10/asyncio/base_events.py", line 646, in run_until_complete
    return future.result()
  File "/Volumes/SONICDRIVE/SONICNewProjects/Aug-1-User-Cafe-Models/app/app_data/seed_magic_v1/seed_db.py", line 163, in main
    await seed_database()
  File "/Volumes/SONICDRIVE/SONICNewProjects/Aug-1-User-Cafe-Models/app/app_data/seed_magic_v1/seed_db.py", line 13, in seed_database
    result = await db.execute(select(CategoryModel))
  File "/Volumes/SONICDRIVE/SONICNewProjects/Aug-1-User-Cafe-Models/venv/lib/python3.10/site-packages/sqlalchemy/ext/asyncio/session.py", line 463, in execute
    result = await greenlet_spawn(
  File "/Volumes/SONICDRIVE/SONICNewProjects/Aug-1-User-Cafe-Models/venv/lib/python3.10/site-packages/sqlalchemy/util/_concurrency_py3k.py", line 201, in greenlet_spawn
    result = context.throw(*sys.exc_info())
  File "/Volumes/SONICDRIVE/SONICNewProjects/Aug-1-User-Cafe-Models/venv/lib/python3.10/site-packages/sqlalchemy/orm/session.py", line 2365, in execute
    return self._execute_internal(
  File "/Volumes/SONICDRIVE/SONICNewProjects/Aug-1-User-Cafe-Models/venv/lib/python3.10/site-packages/sqlalchemy/orm/session.py", line 2251, in _execute_internal
    result: Result[Any] = compile_state_cls.orm_execute_statement(
  File "/Volumes/SONICDRIVE/SONICNewProjects/Aug-1-User-Cafe-Models/venv/lib/python3.10/site-packages/sqlalchemy/orm/context.py", line 306, in orm_execute_statement
    result = conn.execute(
  File "/Volumes/SONICDRIVE/SONICNewProjects/Aug-1-User-Cafe-Models/venv/lib/python3.10/site-packages/sqlalchemy/engine/base.py", line 1413, in execute
    return meth(
  File "/Volumes/SONICDRIVE/SONICNewProjects/Aug-1-User-Cafe-Models/venv/lib/python3.10/site-packages/sqlalchemy/sql/elements.py", line 526, in _execute_on_connection
    return connection._execute_clauseelement(
  File "/Volumes/SONICDRIVE/SONICNewProjects/Aug-1-User-Cafe-Models/venv/lib/python3.10/site-packages/sqlalchemy/engine/base.py", line 1635, in _execute_clauseelement
    ret = self._execute_context(
  File "/Volumes/SONICDRIVE/SONICNewProjects/Aug-1-User-Cafe-Models/venv/lib/python3.10/site-packages/sqlalchemy/engine/base.py", line 1840, in _execute_context
    return self._exec_single_context(
  File "/Volumes/SONICDRIVE/SONICNewProjects/Aug-1-User-Cafe-Models/venv/lib/python3.10/site-packages/sqlalchemy/engine/base.py", line 1980, in _exec_single_context
    self._handle_dbapi_exception(
  File "/Volumes/SONICDRIVE/SONICNewProjects/Aug-1-User-Cafe-Models/venv/lib/python3.10/site-packages/sqlalchemy/engine/base.py", line 2349, in _handle_dbapi_exception
    raise sqlalchemy_exception.with_traceback(exc_info[2]) from e
  File "/Volumes/SONICDRIVE/SONICNewProjects/Aug-1-User-Cafe-Models/venv/lib/python3.10/site-packages/sqlalchemy/engine/base.py", line 1961, in _exec_single_context
    self.dialect.do_execute(
  File "/Volumes/SONICDRIVE/SONICNewProjects/Aug-1-User-Cafe-Models/venv/lib/python3.10/site-packages/sqlalchemy/engine/default.py", line 944, in do_execute
    cursor.execute(statement, parameters)
  File "/Volumes/SONICDRIVE/SONICNewProjects/Aug-1-User-Cafe-Models/venv/lib/python3.10/site-packages/sqlalchemy/dialects/sqlite/aiosqlite.py", line 177, in execute
    self._adapt_connection._handle_exception(error)
  File "/Volumes/SONICDRIVE/SONICNewProjects/Aug-1-User-Cafe-Models/venv/lib/python3.10/site-packages/sqlalchemy/dialects/sqlite/aiosqlite.py", line 337, in _handle_exception
    raise error
  File "/Volumes/SONICDRIVE/SONICNewProjects/Aug-1-User-Cafe-Models/venv/lib/python3.10/site-packages/sqlalchemy/dialects/sqlite/aiosqlite.py", line 159, in execute
    self.await_(_cursor.execute(operation, parameters))
  File "/Volumes/SONICDRIVE/SONICNewProjects/Aug-1-User-Cafe-Models/venv/lib/python3.10/site-packages/sqlalchemy/util/_concurrency_py3k.py", line 132, in await_only
    return current.parent.switch(awaitable)  # type: ignore[no-any-return,attr-defined] # noqa: E501
  File "/Volumes/SONICDRIVE/SONICNewProjects/Aug-1-User-Cafe-Models/venv/lib/python3.10/site-packages/sqlalchemy/util/_concurrency_py3k.py", line 196, in greenlet_spawn
    value = await result
  File "/Volumes/SONICDRIVE/SONICNewProjects/Aug-1-User-Cafe-Models/venv/lib/python3.10/site-packages/aiosqlite/cursor.py", line 40, in execute
    await self._execute(self._cursor.execute, sql, parameters)
  File "/Volumes/SONICDRIVE/SONICNewProjects/Aug-1-User-Cafe-Models/venv/lib/python3.10/site-packages/aiosqlite/cursor.py", line 32, in _execute
    return await self._conn._execute(fn, *args, **kwargs)
  File "/Volumes/SONICDRIVE/SONICNewProjects/Aug-1-User-Cafe-Models/venv/lib/python3.10/site-packages/aiosqlite/core.py", line 122, in _execute
    return await future
  File "/Volumes/SONICDRIVE/SONICNewProjects/Aug-1-User-Cafe-Models/venv/lib/python3.10/site-packages/aiosqlite/core.py", line 105, in run
    result = function()
sqlalchemy.exc.OperationalError: (sqlite3.OperationalError) no such table: categories
[SQL: SELECT categories.id, categories.name
FROM categories]
(Background on this error at: https://sqlalche.me/e/20/e3q8)

Process finished with exit code 1